<?xml version="1.0" ?>
<robot name="mouse" xmlns:xacro="http://www.ros.org/wiki/xacro">
	<xacro:property name="wheel_sep" value="0.069"/>
	<xacro:property name="wheel_dia" value="0.034"/>
	<xacro:property name="wheel_torque" value="0.015"/>
	<xacro:property name="wheel_veloc" value="105"/>

	<link name="base_link">
		<visual>
			<geometry>
				<mesh filename="package://mouse_description/meshes/mouse_base.dae" scale="1 1 1"/>
			</geometry>
		</visual>

		<collision name="base_link_collision">
			<geometry>
				<mesh filename="package://mouse_description/meshes/mouse_base.dae" scale="1 1 1"/>
			</geometry>
		</collision>

		<inertial>
			<origin xyz="0 -0.004502 0.011265" rpy="0 0 0"/>
			<mass value="0.077"/>
			<inertia
        		ixx="1.956e-5" ixy="3.869e-18" ixz="0.0"
        		iyy="1.775e-5" iyz="2.795e-7"
        		izz="3.367e-5"/>
		</inertial>

		<gazebo reference="base_link">
			<mu1>0.1</mu1>
			<mu2>0.1</mu2>
			<kp>1000000.0</kp>
			<kd>100.0</kd>
			<minDepth>0.0001</minDepth>
			<maxVel>1.0</maxVel>
		</gazebo>
	</link>

	<!-- Actuation -->
	<link name="left_wheel">
		<visual>
			<geometry>
				<mesh filename="package://mouse_description/meshes/mouse_wheel.dae" scale="1 1 1"/>
			</geometry>
		</visual>

		<collision name="left_wheel_collision">
			<geometry>
				<mesh filename="package://mouse_description/meshes/mouse_wheel.dae" scale="1 1 1"/>
			</geometry>
		</collision>

		<inertial>
			<mass value="0.015"/>
			<inertia
        		ixx="2.196e-6" ixy="0.0" ixz="0.0"
        		iyy="1.146e-6" iyz="0.0"
        		izz="1.146e-6"/>
		</inertial>
	</link>

	<link name="right_wheel">
		<visual>
			<geometry>
				<mesh filename="package://mouse_description/meshes/mouse_wheel.dae" scale="1 1 1"/>
			</geometry>
		</visual>

		<collision name="right_wheel_collision">
			<geometry>
				<mesh filename="package://mouse_description/meshes/mouse_wheel.dae" scale="1 1 1"/>
			</geometry>
		</collision>

		<inertial>
			<mass value="0.015"/>
			<inertia
        		ixx="2.196e-6" ixy="0.0" ixz="0.0"
        		iyy="1.146e-6" iyz="0.0"
        		izz="1.146e-6"/>
		</inertial>
	</link>

	<joint name="left_mot" type="continuous">
		<parent link="base_link"/>
		<child link="left_wheel"/>
		<origin xyz="${wheel_sep/2} 0 ${wheel_dia/2}" rpy="0 0 0"/>
		<axis xyz="-1 0 0"/>
		<dynamics friction="0.01"/>
		<limit effort="${wheel_torque}" velocity="${wheel_veloc}"/>
	</joint>

	<joint name="right_mot" type="continuous">
		<parent link="base_link"/>
		<child link="right_wheel"/>
		<origin xyz="${-wheel_sep/2} 0 ${wheel_dia/2}" rpy="0 0 0"/>
		<axis xyz="-1 0 0"/>
		<dynamics friction="0.01"/>
		<limit effort="${wheel_torque}" velocity="${wheel_veloc}"/>
	</joint>

	<gazebo reference="left_wheel">
		<mu1>1.0</mu1>
		<mu2>1.0</mu2>
		<kp>1000000.0</kp>
		<kd>100.0</kd>
		<minDepth>0.0001</minDepth>
		<maxVel>1.0</maxVel>
		<material>Gazebo/Black</material>
	</gazebo>

	<gazebo reference="right_wheel">
		<mu1>1.0</mu1>
		<mu2>1.0</mu2>
		<kp>1000000.0</kp>
		<kd>100.0</kd>
		<minDepth>0.0001</minDepth>
		<maxVel>1.0</maxVel>
		<material>Gazebo/Black</material>
	</gazebo>

	<!-- Gazebo Actuation -->
	<gazebo>
		<plugin name="differential_drive_controller" filename="libgazebo_ros_diff_drive.so">
			<rosDebugLevel>0</rosDebugLevel>
			<alwaysOn>true</alwaysOn>
			<updateRate>120</updateRate>
			
			<leftJoint>right_mot</leftJoint>
			<rightJoint>left_mot</rightJoint>
			
			<wheelAcceleration>0</wheelAcceleration>
			<wheelSeparation>${wheel_sep}</wheelSeparation>
			<wheelDiameter>${wheel_dia}</wheelDiameter>
			<wheelTorque>${wheel_torque}</wheelTorque>
			
			<commandTopic>cmd_vel</commandTopic>
			<odometryTopic>odom</odometryTopic>

			<!-- world == perfect positioning -->
			<odometrySource>world</odometrySource>

			<odometryFrame>map</odometryFrame>
			<robotBaseFrame>base</robotBaseFrame>

			<publishTf>1</publishTf>
			<publishWheelTF>false</publishWheelTF>
			<publishOdomTF>true</publishOdomTF>
			<publishWheelJointState>false</publishWheelJointState>
		</plugin>
	</gazebo>

	<!-- Sensors -->

	<!-- Color Sensor (Camera) -->
	<link name="front_cam">
		<visual>
			<geometry>
				<box size="0.008 0.008 0.008"/>
			</geometry>
		</visual>

		<collision name="front_cam_collision">
			<geometry>
				<box size="0.008 0.008 0.008"/>
			</geometry>
		</collision>

		<inertial>
			<mass value="1e-5"/>
			<inertia
        		ixx="1e-6" ixy="0.0" ixz="0.0"
        		iyy="1e-6" iyz="0.0"
        		izz="1e-6"/>
		</inertial>
	</link>

	<joint name="front_cam_mnt" type="fixed">
		<origin xyz="0 0 0.027" rpy="0 0 1.5708"/>
		<parent link="base_link"/>
		<child link="front_cam"/>
	</joint>

	<gazebo reference="front_cam">
		<material>Gazebo/Blue</material>

		<sensor name="front_cam" type="camera">
			<update_rate>24</update_rate>
			<camera name="front_cam">
				<horizontal_fov>2</horizontal_fov>
				<image>
					<width>640</width>
					<height>480</height>
					<format>R8G8B8</format>
				</image>
				<clip>
					<near>0.001</near>
					<far>0.5</far>
				</clip>
			</camera>
			<plugin name="gazebo_ros_camera" filename="libgazebo_ros_camera.so">
				<imageTopicName>image_raw</imageTopicName>
				<cameraInfoTopicName>camera_info</cameraInfoTopicName>
				<!-- incorrect TF frame -->
				<frameName>base</frameName>
			</plugin>
		</sensor>
	</gazebo>

	<!-- Bumper sensor -->
	<link name="left_bump">
		<visual>
			<geometry>
				<sphere radius="0.005"/>
			</geometry>
		</visual>

		<collision name="left_bump_collision">
			<geometry>
				<sphere radius="0.005"/>
			</geometry>
		</collision>

		<inertial>
			<mass value="1e-5"/>
			<inertia
        		ixx="1e-6" ixy="0.0" ixz="0.0"
        		iyy="1e-6" iyz="0.0"
        		izz="1e-6"/>
		</inertial>
	</link>

	<link name="right_bump">
		<visual>
			<geometry>
				<sphere radius="0.005"/>
			</geometry>
		</visual>

		<collision name="right_bump_collision">
			<geometry>
				<sphere radius="0.005"/>
			</geometry>
		</collision>

		<inertial>
			<mass value="1e-5"/>
			<inertia
        		ixx="1e-6" ixy="0.0" ixz="0.0"
        		iyy="1e-6" iyz="0.0"
        		izz="1e-6"/>
		</inertial>
	</link>

	<link name="left_front_bump">
		<visual>
			<geometry>
				<sphere radius="0.005"/>
			</geometry>
		</visual>

		<collision name="left_front_bump_collision">
			<geometry>
				<sphere radius="0.005"/>
			</geometry>
		</collision>

		<inertial>
			<mass value="1e-5"/>
			<inertia
        		ixx="1e-6" ixy="0.0" ixz="0.0"
        		iyy="1e-6" iyz="0.0"
        		izz="1e-6"/>
		</inertial>
	</link>

	<link name="right_front_bump">
		<visual>
			<geometry>
				<sphere radius="0.005"/>
			</geometry>
		</visual>

		<collision name="right_front_bump_collision">
			<geometry>
				<sphere radius="0.005"/>
			</geometry>
		</collision>

		<inertial>
			<mass value="1e-5"/>
			<inertia
        		ixx="1e-6" ixy="0.0" ixz="0.0"
        		iyy="1e-6" iyz="0.0"
        		izz="1e-6"/>
		</inertial>
	</link>

	<joint name="left_bump_mnt" type="fixed">
		<origin xyz="-0.0256 0.0207 0.013" rpy="0 0 0"/>
		<parent link="base_link"/>
		<child link="left_bump"/>
	</joint>

	<joint name="right_bump_mnt" type="fixed">
		<origin xyz="0.0256 0.0207 0.013" rpy="0 0 0"/>
		<parent link="base_link"/>
		<child link="right_bump"/>
	</joint>

	<joint name="left_front_bump_mnt" type="fixed">
		<origin xyz="-0.009152 0.032074 0.013" rpy="0 0 0"/>
		<parent link="base_link"/>
		<child link="left_front_bump"/>
	</joint>

	<joint name="right_front_bump_mnt" type="fixed">
		<origin xyz="0.009152 0.032074 0.013" rpy="0 0 0"/>
		<parent link="base_link"/>
		<child link="right_front_bump"/>
	</joint>

	<gazebo reference="left_bump_mnt">
		<preserveFixedJoint>true</preserveFixedJoint>
	</gazebo>

	<gazebo reference="right_bump_mnt">
		<preserveFixedJoint>true</preserveFixedJoint>
	</gazebo>

	<gazebo reference="left_front_bump_mnt">
		<preserveFixedJoint>true</preserveFixedJoint>
	</gazebo>

	<gazebo reference="right_front_bump_mnt">
		<preserveFixedJoint>true</preserveFixedJoint>
	</gazebo>

	<gazebo reference="left_bump">
		<mu1>1.0</mu1>
		<mu2>1.0</mu2>
		<kp>1000000.0</kp>
		<kd>100.0</kd>
		<minDepth>0.0001</minDepth>
		<maxVel>1.0</maxVel>
		<material>Gazebo/Blue</material>

		<sensor name="left_bump" type="contact">
			<updateRate>24</updateRate>
			<contact>
				<collision>left_bump_collision_collision</collision>
			</contact>
			<plugin name="gazebo_ros_bumper" filename="libgazebo_ros_bumper.so">
				<bumperTopicName>bumper</bumperTopicName>
				<frameName>left_bump</frameName>
			</plugin>
		</sensor>
	</gazebo>

	<gazebo reference="right_bump">
		<mu1>1.0</mu1>
		<mu2>1.0</mu2>
		<kp>1000000.0</kp>
		<kd>100.0</kd>
		<minDepth>0.0001</minDepth>
		<maxVel>1.0</maxVel>
		<material>Gazebo/Blue</material>

		<sensor name="right_bump" type="contact">
			<updateRate>24</updateRate>
			<contact>
				<collision>right_bump_collision_collision</collision>
			</contact>
			<plugin name="gazebo_ros_bumper" filename="libgazebo_ros_bumper.so">
				<bumperTopicName>bumper</bumperTopicName>
				<frameName>right_bump</frameName>
			</plugin>
		</sensor>
	</gazebo>

	<gazebo reference="left_front_bump">
		<mu1>1.0</mu1>
		<mu2>1.0</mu2>
		<kp>1000000.0</kp>
		<kd>100.0</kd>
		<minDepth>0.0001</minDepth>
		<maxVel>1.0</maxVel>
		<material>Gazebo/Blue</material>

		<sensor name="left_front_bump" type="contact">
			<updateRate>24</updateRate>
			<contact>
				<collision>left_front_bump_collision_collision</collision>
			</contact>
			<plugin name="gazebo_ros_bumper" filename="libgazebo_ros_bumper.so">
				<bumperTopicName>bumper</bumperTopicName>
				<frameName>left_front_bump</frameName>
			</plugin>
		</sensor>
	</gazebo>

	<gazebo reference="right_front_bump">
		<mu1>1.0</mu1>
		<mu2>1.0</mu2>
		<kp>1000000.0</kp>
		<kd>100.0</kd>
		<minDepth>0.0001</minDepth>
		<maxVel>1.0</maxVel>
		<material>Gazebo/Blue</material>

		<sensor name="right_front_bump" type="contact">
			<updateRate>24</updateRate>
			<contact>
				<collision>right_front_bump_collision_collision</collision>
			</contact>
			<plugin name="gazebo_ros_bumper" filename="libgazebo_ros_bumper.so">
				<bumperTopicName>bumper</bumperTopicName>
				<frameName>right_front_bump</frameName>
			</plugin>
		</sensor>
	</gazebo>

	<!-- TODO add compass sensor -->

	<!-- TODO add GPS sensor -->
</robot>
